2022-05-09T21:48:41.668360482Z stderr F Traceback (most recent call last):
2022-05-09T21:48:41.66843129Z stderr F   File "/app/server.py", line 152, in <module>
2022-05-09T21:48:41.672495398Z stderr F     initDatabase()
2022-05-09T21:48:41.672542007Z stderr F   File "/app/server.py", line 111, in initDatabase
2022-05-09T21:48:41.672567108Z stderr F     connect = pymysql.connect(**config)
2022-05-09T21:48:41.672589874Z stderr F   File "/usr/local/lib/python3.9/site-packages/pymysql/connections.py", line 353, in __init__
2022-05-09T21:48:41.672652113Z stderr F     self.connect()
2022-05-09T21:48:41.672663829Z stderr F   File "/usr/local/lib/python3.9/site-packages/pymysql/connections.py", line 632, in connect
2022-05-09T21:48:41.672673746Z stderr F     self._get_server_information()
2022-05-09T21:48:41.67268269Z stderr F   File "/usr/local/lib/python3.9/site-packages/pymysql/connections.py", line 1055, in _get_server_information
2022-05-09T21:48:41.672691673Z stderr F     packet = self._read_packet()
2022-05-09T21:48:41.67269832Z stderr F   File "/usr/local/lib/python3.9/site-packages/pymysql/connections.py", line 692, in _read_packet
2022-05-09T21:48:41.672705174Z stderr F     packet_header = self._read_bytes(4)
2022-05-09T21:48:41.672712029Z stderr F   File "/usr/local/lib/python3.9/site-packages/pymysql/connections.py", line 748, in _read_bytes
2022-05-09T21:48:41.672718163Z stderr F     raise err.OperationalError(
2022-05-09T21:48:41.672724964Z stderr F pymysql.err.OperationalError: (2013, 'Lost connection to MySQL server during query')
