2022-06-13T02:29:44.932945782Z stderr F Traceback (most recent call last):
2022-06-13T02:29:44.932988824Z stderr F   File "/usr/local/lib/python3.9/site-packages/pymysql/connections.py", line 613, in connect
2022-06-13T02:29:44.933194274Z stderr F     sock = socket.create_connection(
2022-06-13T02:29:44.933203677Z stderr F   File "/usr/local/lib/python3.9/socket.py", line 844, in create_connection
2022-06-13T02:29:44.933806651Z stderr F     raise err
2022-06-13T02:29:44.933826185Z stderr F   File "/usr/local/lib/python3.9/socket.py", line 832, in create_connection
2022-06-13T02:29:44.934214438Z stderr F     sock.connect(sa)
2022-06-13T02:29:44.934225159Z stderr F ConnectionRefusedError: [Errno 111] Connection refused
2022-06-13T02:29:44.93422804Z stderr F 
2022-06-13T02:29:44.934231203Z stderr F During handling of the above exception, another exception occurred:
2022-06-13T02:29:44.934233599Z stderr F 
2022-06-13T02:29:44.934236902Z stderr F Traceback (most recent call last):
2022-06-13T02:29:44.934239411Z stderr F   File "/app/server.py", line 152, in <module>
2022-06-13T02:29:44.934429513Z stderr F     initDatabase()
2022-06-13T02:29:44.934438984Z stderr F   File "/app/server.py", line 111, in initDatabase
2022-06-13T02:29:44.934554137Z stderr F     connect = pymysql.connect(**config)
2022-06-13T02:29:44.934569315Z stderr F   File "/usr/local/lib/python3.9/site-packages/pymysql/connections.py", line 353, in __init__
2022-06-13T02:29:44.945897491Z stderr F     self.connect()
2022-06-13T02:29:44.946160344Z stderr F   File "/usr/local/lib/python3.9/site-packages/pymysql/connections.py", line 664, in connect
2022-06-13T02:29:44.946955489Z stderr F     raise exc
2022-06-13T02:29:44.947019282Z stderr F pymysql.err.OperationalError: (2003, "Can't connect to MySQL server on 'ts-voucher-mysql' ([Errno 111] Connection refused)")
